WARNING  urllib3.connectionpool:connectionpool.py:812 Retrying (Retry(total=2, connect=None, read=None, redirect=None, status=None)) after connection broken by 'NewConnectionError('<urllib3.connection.HTTPConnection object at 0x7f523a8138d0>: Failed to establish a new connection: [Errno 111] Connection refused')': /session/df34cee1-4380-406e-b321-a5d7935f6f4b/screenshot
WARNING  urllib3.connectionpool:connectionpool.py:812 Retrying (Retry(total=1, connect=None, read=None, redirect=None, status=None)) after connection broken by 'NewConnectionError('<urllib3.connection.HTTPConnection object at 0x7f523a811590>: Failed to establish a new connection: [Errno 111] Connection refused')': /session/df34cee1-4380-406e-b321-a5d7935f6f4b/screenshot
WARNING  urllib3.connectionpool:connectionpool.py:812 Retrying (Retry(total=0, connect=None, read=None, redirect=None, status=None)) after connection broken by 'NewConnectionError('<urllib3.connection.HTTPConnection object at 0x7f523a7e0b10>: Failed to establish a new connection: [Errno 111] Connection refused')': /session/df34cee1-4380-406e-b321-a5d7935f6f4b/screenshot