WARNING  urllib3.connectionpool:connectionpool.py:812 Retrying (Retry(total=2, connect=None, read=None, redirect=None, status=None)) after connection broken by 'NewConnectionError('<urllib3.connection.HTTPConnection object at 0x7f1f3ad328d0>: Failed to establish a new connection: [Errno 111] Connection refused')': /session/11c0fd2a-6a31-4555-848b-60e3ebe5ef8c/screenshot
WARNING  urllib3.connectionpool:connectionpool.py:812 Retrying (Retry(total=1, connect=None, read=None, redirect=None, status=None)) after connection broken by 'NewConnectionError('<urllib3.connection.HTTPConnection object at 0x7f1f3ae93610>: Failed to establish a new connection: [Errno 111] Connection refused')': /session/11c0fd2a-6a31-4555-848b-60e3ebe5ef8c/screenshot
WARNING  urllib3.connectionpool:connectionpool.py:812 Retrying (Retry(total=0, connect=None, read=None, redirect=None, status=None)) after connection broken by 'NewConnectionError('<urllib3.connection.HTTPConnection object at 0x7f1f3ae65510>: Failed to establish a new connection: [Errno 111] Connection refused')': /session/11c0fd2a-6a31-4555-848b-60e3ebe5ef8c/screenshot