WARNING  urllib3.connectionpool:connectionpool.py:812 Retrying (Retry(total=2, connect=None, read=None, redirect=None, status=None)) after connection broken by 'NewConnectionError('<urllib3.connection.HTTPConnection object at 0x7f5239595250>: Failed to establish a new connection: [Errno 111] Connection refused')': /session/6013af45-d253-416c-8a0d-1536b801d43a/screenshot
WARNING  urllib3.connectionpool:connectionpool.py:812 Retrying (Retry(total=1, connect=None, read=None, redirect=None, status=None)) after connection broken by 'NewConnectionError('<urllib3.connection.HTTPConnection object at 0x7f5239595ed0>: Failed to establish a new connection: [Errno 111] Connection refused')': /session/6013af45-d253-416c-8a0d-1536b801d43a/screenshot
WARNING  urllib3.connectionpool:connectionpool.py:812 Retrying (Retry(total=0, connect=None, read=None, redirect=None, status=None)) after connection broken by 'NewConnectionError('<urllib3.connection.HTTPConnection object at 0x7f5239597790>: Failed to establish a new connection: [Errno 111] Connection refused')': /session/6013af45-d253-416c-8a0d-1536b801d43a/screenshot