WARNING  urllib3.connectionpool:connectionpool.py:812 Retrying (Retry(total=2, connect=None, read=None, redirect=None, status=None)) after connection broken by 'NewConnectionError('<urllib3.connection.HTTPConnection object at 0x7f52395eb850>: Failed to establish a new connection: [Errno 111] Connection refused')': /session/c1bfa58d-8234-47db-9988-2783aa52b4a6/screenshot
WARNING  urllib3.connectionpool:connectionpool.py:812 Retrying (Retry(total=1, connect=None, read=None, redirect=None, status=None)) after connection broken by 'NewConnectionError('<urllib3.connection.HTTPConnection object at 0x7f52395e9bd0>: Failed to establish a new connection: [Errno 111] Connection refused')': /session/c1bfa58d-8234-47db-9988-2783aa52b4a6/screenshot
WARNING  urllib3.connectionpool:connectionpool.py:812 Retrying (Retry(total=0, connect=None, read=None, redirect=None, status=None)) after connection broken by 'NewConnectionError('<urllib3.connection.HTTPConnection object at 0x7f52395eadd0>: Failed to establish a new connection: [Errno 111] Connection refused')': /session/c1bfa58d-8234-47db-9988-2783aa52b4a6/screenshot