WARNING  urllib3.connectionpool:connectionpool.py:812 Retrying (Retry(total=2, connect=None, read=None, redirect=None, status=None)) after connection broken by 'NewConnectionError('<urllib3.connection.HTTPConnection object at 0x7f1f39a20210>: Failed to establish a new connection: [Errno 111] Connection refused')': /session/d53d9879-dbba-4912-b3bb-fcd5b0d2ba9b/screenshot
WARNING  urllib3.connectionpool:connectionpool.py:812 Retrying (Retry(total=1, connect=None, read=None, redirect=None, status=None)) after connection broken by 'NewConnectionError('<urllib3.connection.HTTPConnection object at 0x7f1f39a21610>: Failed to establish a new connection: [Errno 111] Connection refused')': /session/d53d9879-dbba-4912-b3bb-fcd5b0d2ba9b/screenshot
WARNING  urllib3.connectionpool:connectionpool.py:812 Retrying (Retry(total=0, connect=None, read=None, redirect=None, status=None)) after connection broken by 'NewConnectionError('<urllib3.connection.HTTPConnection object at 0x7f1f39b70a10>: Failed to establish a new connection: [Errno 111] Connection refused')': /session/d53d9879-dbba-4912-b3bb-fcd5b0d2ba9b/screenshot