WARNING  urllib3.connectionpool:connectionpool.py:812 Retrying (Retry(total=2, connect=None, read=None, redirect=None, status=None)) after connection broken by 'NewConnectionError('<urllib3.connection.HTTPConnection object at 0x7f1f39b9d7d0>: Failed to establish a new connection: [Errno 111] Connection refused')': /session/1373bde0-385d-4878-8ce5-636289f27341/screenshot
WARNING  urllib3.connectionpool:connectionpool.py:812 Retrying (Retry(total=1, connect=None, read=None, redirect=None, status=None)) after connection broken by 'NewConnectionError('<urllib3.connection.HTTPConnection object at 0x7f1f39b9f4d0>: Failed to establish a new connection: [Errno 111] Connection refused')': /session/1373bde0-385d-4878-8ce5-636289f27341/screenshot
WARNING  urllib3.connectionpool:connectionpool.py:812 Retrying (Retry(total=0, connect=None, read=None, redirect=None, status=None)) after connection broken by 'NewConnectionError('<urllib3.connection.HTTPConnection object at 0x7f1f3994ead0>: Failed to establish a new connection: [Errno 111] Connection refused')': /session/1373bde0-385d-4878-8ce5-636289f27341/screenshot