WARNING  urllib3.connectionpool:connectionpool.py:812 Retrying (Retry(total=2, connect=None, read=None, redirect=None, status=None)) after connection broken by 'NewConnectionError('<urllib3.connection.HTTPConnection object at 0x7f52395ba850>: Failed to establish a new connection: [Errno 111] Connection refused')': /session/44acdeb0-0162-4df4-96d6-32105a3d6430/screenshot
WARNING  urllib3.connectionpool:connectionpool.py:812 Retrying (Retry(total=1, connect=None, read=None, redirect=None, status=None)) after connection broken by 'NewConnectionError('<urllib3.connection.HTTPConnection object at 0x7f52395ba710>: Failed to establish a new connection: [Errno 111] Connection refused')': /session/44acdeb0-0162-4df4-96d6-32105a3d6430/screenshot
WARNING  urllib3.connectionpool:connectionpool.py:812 Retrying (Retry(total=0, connect=None, read=None, redirect=None, status=None)) after connection broken by 'NewConnectionError('<urllib3.connection.HTTPConnection object at 0x7f52395b8150>: Failed to establish a new connection: [Errno 111] Connection refused')': /session/44acdeb0-0162-4df4-96d6-32105a3d6430/screenshot